Workbook

Sheet parts
A1: partID | B1: label | C1: partType | D1: partDesc | E1: partInstr | F1: fKAliasID | G1: domain | H1: specimenSet | I1: compartmentSet | J1: group | K1: class | L1: nomenclature | M1: ontologyRef | N1: latExp | O1: mmaSet | P1: unitSet | Q1: aggregationScale | R1: aggregationSet | S1: qualityIndSet | T1: missingnessSet | U1: status | V1: firstReleased | W1: lastUpdated | X1: changes | Y1: protocolSteps | Z1: protocolStepsRequired | AA1: protocolStepsOrder | AB1: protocolRelationships | AC1: protocolRelationshipsRequired | AD1: protocolRelationshipsOrder | AE1: measures | AF1: measuresRequired | AG1: measuresOrder | AH1: measureSets | AI1: measureSetsRequired | AJ1: measureSetsOrder | AK1: datasets | AL1: datasetsRequired | AM1: datasetsOrder | AN1: sites | AO1: sitesRequired | AP1: sitesOrder | AQ1: samples | AR1: samplesRequired | AS1: samplesOrder | AT1: addresses | AU1: addressesRequired | AV1: addressesOrder | AW1: contacts | AX1: contactsRequired | AY1: contactsOrder | AZ1: organizations | BA1: organizationsRequired | BB1: organizationsOrder | BC1: instruments | BD1: instrumentsRequired | BE1: instrumentsOrder | BF1: polygons | BG1: polygonsRequired | BH1: polygonsOrder | BI1: languages | BJ1: languagesRequired | BK1: languagesOrder | BL1: translations | BM1: translationsRequired | BN1: translationsOrder | BO1: parts | BP1: partsRequired | BQ1: partsOrder | BR1: sets | BS1: setsRequired | BT1: setsOrder | BU1: qualityReports | BV1: qualityReportsRequired | BW1: qualityReportsOrder | BX1: sampleRelationships | BY1: sampleRelationshipsRequired | BZ1: sampleRelationshipsOrder | CA1: protocols | CB1: protocolsRequired | CC1: protocolsOrder | CD1: countries | CE1: countriesRequired | CF1: countriesOrder | CG1: zones | CH1: zonesRequired | CI1: zonesOrder | CJ1: wideNames | CK1: wideNamesRequired | CL1: wideNamesOrder | CM1: refLink | CN1: dataType | CO1: minValue | CP1: maxValue | CQ1: minLength | CR1: maxLength
A2: a1306s | B2: a1306s delta-variant gene target | C2: measurements | D2: a1306s delta-variant mutation gene target | E2: NA | F2: NA | G2: bio | H2: saSpecimenSet | I2: anyCompartmentSet | J2: sarsCov2 | K2: pcr | L2: naNomenclature | M2: NA | N2: NA | O2: NA | P2: geneticUnitSet | Q2: seeUnitAggScale | R2: otherAggrSet | S2: pcrQualitySet | T2: genMissingnessSet | U2: active | V2: 2.0.0 | W2: 2.0.0 | X2: added in V2.0.0 | Y2: input | Z2: NA | AA2: NA | AB2: NA | AC2: NA | AD2: NA | AE2: input | AF2: NA | AG2: NA | AH2: NA | AI2: NA | AJ2: NA | AK2: NA | AL2: NA | AM2: NA | AN2: NA | AO2: NA | AP2: NA | AQ2: NA | AR2: NA | AS2: NA | AT2: NA | AU2: NA | AV2: NA | AW2: NA | AX2: NA | AY2: NA | AZ2: NA | BA2: NA | BB2: NA | BC2: NA | BD2: NA | BE2: NA | BF2: NA | BG2: NA | BH2: NA | BI2: NA | BJ2: NA | BK2: NA | BL2: NA | BM2: NA | BN2: NA | BO2: NA | BP2: NA | BQ2: NA | BR2: NA | BS2: NA | BT2: NA | BU2: NA | BV2: NA | BW2: NA | BX2: NA | BY2: NA | BZ2: NA | CA2: NA | CB2: NA | CC2: NA | CD2: NA | CE2: NA | CF2: NA | CG2: NA | CH2: NA | CI2: NA | CJ2: input | CK2: NA | CL2: NA | CM2: NA | CN2: seeUnitData | CO2: seeUnitVal | CP2: seeUnitVal | CQ2: NA | CR2: NA
A3: a1918v | B3: a1918v delta-variant gene target | C3: measurements | D3: a1918v delta-variant mutation gene target | E3: NA | F3: NA | G3: bio | H3: saSpecimenSet | I3: anyCompartmentSet | J3: sarsCov2 | K3: pcr | L3: naNomenclature | M3: NA | N3: NA | O3: NA | P3: geneticUnitSet | Q3: seeUnitAggScale | R3: otherAggrSet | S3: pcrQualitySet | T3: genMissingnessSet | U3: active | V3: 2.0.0 | W3: 2.0.0 | X3: added in V2.0.0 | Y3: input | Z3: NA | AA3: NA | AB3: NA | AC3: NA | AD3: NA | AE3: input | AF3: NA | AG3: NA | AH3: NA | AI3: NA | AJ3: NA | AK3: NA | AL3: NA | AM3: NA | AN3: NA | AO3: NA | AP3: NA | AQ3: NA | AR3: NA | AS3: NA | AT3: NA | AU3: NA | AV3: NA | AW3: NA | AX3: NA | AY3: NA | AZ3: NA | BA3: NA | BB3: NA | BC3: NA | BD3: NA | BE3: NA | BF3: NA | BG3: NA | BH3: NA | BI3: NA | BJ3: NA | BK3: NA | BL3: NA | BM3: NA | BN3: NA | BO3: NA | BP3: NA | BQ3: NA | BR3: NA | BS3: NA | BT3: NA | BU3: NA | BV3: NA | BW3: NA | BX3: NA | BY3: NA | BZ3: NA | CA3: NA | CB3: NA | CC3: NA | CD3: NA | CE3: NA | CF3: NA | CG3: NA | CH3: NA | CI3: NA | CJ3: input | CK3: NA | CL3: NA | CM3: NA | CN3: seeUnitData | CO3: seeUnitVal | CP3: seeUnitVal | CQ3: NA | CR3: NA
A4: a2710t | B4: a2710t omicron-variant gene target | C4: measurements | D4: a2710t omicron-variant mutation gene target | E4: NA | F4: NA | G4: bio | H4: saSpecimenSet | I4: anyCompartmentSet | J4: sarsCov2 | K4: pcr | L4: naNomenclature | M4: NA | N4: NA | O4: NA | P4: geneticUnitSet | Q4: seeUnitAggScale | R4: otherAggrSet | S4: pcrQualitySet | T4: genMissingnessSet | U4: active | V4: 2.0.0 | W4: 2.0.0 | X4: added in V2.0.0 | Y4: input | Z4: NA | AA4: NA | AB4: NA | AC4: NA | AD4: NA | AE4: input | AF4: NA | AG4: NA | AH4: NA | AI4: NA | AJ4: NA | AK4: NA | AL4: NA | AM4: NA | AN4: NA | AO4: NA | AP4: NA | AQ4: NA | AR4: NA | AS4: NA | AT4: NA | AU4: NA | AV4: NA | AW4: NA | AX4: NA | AY4: NA | AZ4: NA | BA4: NA | BB4: NA | BC4: NA | BD4: NA | BE4: NA | BF4: NA | BG4: NA | BH4: NA | BI4: NA | BJ4: NA | BK4: NA | BL4: NA | BM4: NA | BN4: NA | BO4: NA | BP4: NA | BQ4: NA | BR4: NA | BS4: NA | BT4: NA | BU4: NA | BV4: NA | BW4: NA | BX4: NA | BY4: NA | BZ4: NA | CA4: NA | CB4: NA | CC4: NA | CD4: NA | CE4: NA | CF4: NA | CG4: NA | CH4: NA | CI4: NA | CJ4: input | CK4: NA | CL4: NA | CM4: NA | CN4: seeUnitData | CO4: seeUnitVal | CP4: seeUnitVal | CQ4: NA | CR4: NA
A5: a63t | B5: a63t omicron-variant gene target | C5: measurements | D5: a63t omicron-variant mutation gene target | E5: NA | F5: NA | G5: bio | H5: saSpecimenSet | I5: anyCompartmentSet | J5: sarsCov2 | K5: pcr | L5: naNomenclature | M5: NA | N5: NA | O5: NA | P5: geneticUnitSet | Q5: seeUnitAggScale | R5: otherAggrSet | S5: pcrQualitySet | T5: genMissingnessSet | U5: active | V5: 2.0.0 | W5: 2.0.0 | X5: added in V2.0.0 | Y5: input | Z5: NA | AA5: NA | AB5: NA | AC5: NA | AD5: NA | AE5: input | AF5: NA | AG5: NA | AH5: NA | AI5: NA | AJ5: NA | AK5: NA | AL5: NA | AM5: NA | AN5: NA | AO5: NA | AP5: NA | AQ5: NA | AR5: NA | AS5: NA | AT5: NA | AU5: NA | AV5: NA | AW5: NA | AX5: NA | AY5: NA | AZ5: NA | BA5: NA | BB5: NA | BC5: NA | BD5: NA | BE5: NA | BF5: NA | BG5: NA | BH5: NA | BI5: NA | BJ5: NA | BK5: NA | BL5: NA | BM5: NA | BN5: NA | BO5: NA | BP5: NA | BQ5: NA | BR5: NA | BS5: NA | BT5: NA | BU5: NA | BV5: NA | BW5: NA | BX5: NA | BY5: NA | BZ5: NA | CA5: NA | CB5: NA | CC5: NA | CD5: NA | CE5: NA | CF5: NA | CG5: NA | CH5: NA | CI5: NA | CJ5: input | CK5: NA | CL5: NA | CM5: NA | CN5: seeUnitData | CO5: seeUnitVal | CP5: seeUnitVal | CQ5: NA | CR5: NA
A6: a67v | B6: a67v omicron-variant gene target | C6: measurements | D6: a67v omicron-variant mutation gene target | E6: NA | F6: NA | G6: bio | H6: saSpecimenSet | I6: anyCompartmentSet | J6: sarsCov2 | K6: pcr | L6: naNomenclature | M6: NA | N6: NA | O6: NA | P6: geneticUnitSet | Q6: seeUnitAggScale | R6: otherAggrSet | S6: pcrQualitySet | T6: genMissingnessSet | U6: active | V6: 2.0.0 | W6: 2.0.0 | X6: added in V2.0.0 | Y6: input | Z6: NA | AA6: NA | AB6: NA | AC6: NA | AD6: NA | AE6: input | AF6: NA | AG6: NA | AH6: NA | AI6: NA | AJ6: NA | AK6: NA | AL6: NA | AM6: NA | AN6: NA | AO6: NA | AP6: NA | AQ6: NA | AR6: NA | AS6: NA | AT6: NA | AU6: NA | AV6: NA | AW6: NA | AX6: NA | AY6: NA | AZ6: NA | BA6: NA | BB6: NA | BC6: NA | BD6: NA | BE6: NA | BF6: NA | BG6: NA | BH6: NA | BI6: NA | BJ6: NA | BK6: NA | BL6: NA | BM6: NA | BN6: NA | BO6: NA | BP6: NA | BQ6: NA | BR6: NA | BS6: NA | BT6: NA | BU6: NA | BV6: NA | BW6: NA | BX6: NA | BY6: NA | BZ6: NA | CA6: NA | CB6: NA | CC6: NA | CD6: NA | CE6: NA | CF6: NA | CG6: NA | CH6: NA | CI6: NA | CJ6: input | CK6: NA | CL6: NA | CM6: NA | CN6: seeUnitData | CO6: seeUnitVal | CP6: seeUnitVal | CQ6: NA | CR6: NA
A7: a67vDel69Del70 | B7: Omicron Variant a67v del69 and del70 mutations | C7: measurements | D7: Omicron Variant a67v mutation mutation, and del 69 and del70 mutations co-occuring | E7: NA | F7: NA | G7: bio | H7: saSpecimenSet | I7: anyCompartmentSet | J7: omicronGrp | K7: pcr | L7: naNomenclature | M7: NA | N7: NA | O7: NA | P7: geneticUnitSet | Q7: seeUnitAggScale | R7: otherAggrSet | S7: pcrQualitySet | T7: genMissingnessSet | U7: active | V7: 2.2.0 | W7: 2.2.0 | X7: added in V2.2.0 | Y7: input | Z7: NA | AA7: NA | AB7: NA | AC7: NA | AD7: NA | AE7: input | AF7: NA | AG7: NA | AH7: NA | AI7: NA | AJ7: NA | AK7: NA | AL7: NA | AM7: NA | AN7: NA | AO7: NA | AP7: NA | AQ7: NA | AR7: NA | AS7: NA | AT7: NA | AU7: NA | AV7: NA | AW7: NA | AX7: NA | AY7: NA | AZ7: NA | BA7: NA | BB7: NA | BC7: NA | BD7: NA | BE7: NA | BF7: NA | BG7: NA | BH7: NA | BI7: NA | BJ7: NA | BK7: NA | BL7: NA | BM7: NA | BN7: NA | BO7: NA | BP7: NA | BQ7: NA | BR7: NA | BS7: NA | BT7: NA | BU7: NA | BV7: NA | BW7: NA | BX7: NA | BY7: NA | BZ7: NA | CA7: NA | CB7: NA | CC7: NA | CD7: NA | CE7: NA | CF7: NA | CG7: NA | CH7: NA | CI7: NA | CJ7: input | CK7: NA | CL7: NA | CM7: NA | CN7: seeUnitData | CO7: seeUnitVal | CP7: seeUnitVal | CQ7: NA | CR7: NA
A8: aas | B8: Atline Analyzer | C8: categories | D8: Atline analyzer with sampler. | E8: An atline analyzer with sampler. | F8: NA | G8: naDomain | H8: naSpecimenSet | I8: naCompartmentSet | J8: naGroup | K8: naClass | L8: naNomenclature | M8: NA | N8: NA | O8: NA | P8: naUnitSet | Q8: naAggrScale | R8: naAggrSet | S8: NA | T8: NA | U8: active | V8: 1.0.0 | W8: 2.0.0 | X8: description wording, structure | Y8: NA | Z8: NA | AA8: NA | AB8: NA | AC8: NA | AD8: NA | AE8: NA | AF8: NA | AG8: NA | AH8: NA | AI8: NA | AJ8: NA | AK8: NA | AL8: NA | AM8: NA | AN8: NA | AO8: NA | AP8: NA | AQ8: NA | AR8: NA | AS8: NA | AT8: NA | AU8: NA | AV8: NA | AW8: NA | AX8: NA | AY8: NA | AZ8: NA | BA8: NA | BB8: NA | BC8: input | BD8: NA | BE8: NA | BF8: NA | BG8: NA | BH8: NA | BI8: NA | BJ8: NA | BK8: NA | BL8: NA | BM8: NA | BN8: NA | BO8: NA | BP8: NA | BQ8: NA | BR8: NA | BS8: NA | BT8: NA | BU8: NA | BV8: NA | BW8: NA | BX8: NA | BY8: NA | BZ8: NA | CA8: NA | CB8: NA | CC8: NA | CD8: NA | CE8: NA | CF8: NA | CG8: NA | CH8: NA | CI8: NA | CJ8: NA | CK8: NA | CL8: NA | CM8: NA | CN8: varchar | CO8: NA | CP8: NA | CQ8: 0 | CR8: 30
A9: absHum | B9: Absolute humidity | C9: measurements | D9: A measure of the total mass of water vapour present in the air per volume of air. | E9: NA | F9: NA | G9: phy | H9: siSpecimenSet | I9: anyCompartmentSet | J9: siteFeat | K9: humid | L9: naNomenclature | M9: NA | N9: NA | O9: NA | P9: absHumidUnitSet | Q9: seeUnitAggScale | R9: otherAggrSet | S9: genQualitySet | T9: genMissingnessSet | U9: active | V9: 2.0.0 | W9: 2.0.0 | X9: added in V2.0.0 | Y9: input | Z9: NA | AA9: NA | AB9: NA | AC9: NA | AD9: NA | AE9: input | AF9: NA | AG9: NA | AH9: NA | AI9: NA | AJ9: NA | AK9: NA | AL9: NA | AM9: NA | AN9: NA | AO9: NA | AP9: NA | AQ9: NA | AR9: NA | AS9: NA | AT9: NA | AU9: NA | AV9: NA | AW9: NA | AX9: NA | AY9: NA | AZ9: NA | BA9: NA | BB9: NA | BC9: NA | BD9: NA | BE9: NA | BF9: NA | BG9: NA | BH9: NA | BI9: NA | BJ9: NA | BK9: NA | BL9: NA | BM9: NA | BN9: NA | BO9: NA | BP9: NA | BQ9: NA | BR9: NA | BS9: NA | BT9: NA | BU9: NA | BV9: NA | BW9: NA | BX9: NA | BY9: NA | BZ9: NA | CA9: NA | CB9: NA | CC9: NA | CD9: NA | CE9: NA | CF9: NA | CG9: NA | CH9: NA | CI9: NA | CJ9: input | CK9: NA | CL9: NA | CM9: NA | CN9: seeUnitData | CO9: seeUnitVal | CP9: seeUnitVal | CQ9: NA | CR9: NA
A10: absHumidUnitSet | B10: Absolute humidity unit set | C10: unitSets | D10: Unit set for absolute humidity measurements. | E10: NA | F10: NA | G10: naDomain | H10: naSpecimenSet | I10: anyCompartmentSet | J10: naGroup | K10: naClass | L10: naNomenclature | M10: NA | N10: NA | O10: NA | P10: absHumidUnitSet | Q10: seeUnitAggScale | R10: naAggrSet | S10: NA | T10: NA | U10: active | V10: 2.0.0 | W10: 2.0.0 | X10: added in V2.0.0 | Y10: NA | Z10: NA | AA10: NA | AB10: NA | AC10: NA | AD10: NA | AE10: NA | AF10: NA | AG10: NA | AH10: NA | AI10: NA | AJ10: NA | AK10: NA | AL10: NA | AM10: NA | AN10: NA | AO10: NA | AP10: NA | AQ10: NA | AR10: NA | AS10: NA | AT10: NA | AU10: NA | AV10: NA | AW10: NA | AX10: NA | AY10: NA | AZ10: NA | BA10: NA | BB10: NA | BC10: NA | BD10: NA | BE10: NA | BF10: NA | BG10: NA | BH10: NA | BI10: NA | BJ10: NA | BK10: NA | BL10: NA | BM10: NA | BN10: NA | BO10: input | BP10: NA | BQ10: NA | BR10: NA | BS10: NA | BT10: NA | BU10: NA | BV10: NA | BW10: NA | BX10: NA | BY10: NA | BZ10: NA | CA10: NA | CB10: NA | CC10: NA | CD10: NA | CE10: NA | CF10: NA | CG10: NA | CH10: NA | CI10: NA | CJ10: NA | CK10: NA | CL10: NA | CM10: NA | CN10: categorical | CO10: NA | CP10: NA | CQ10: 0 | CR10: 30
A11: ac | B11: Accessions report table Shorthand | C11: shortName | D11: The abbreviated short name used to reference the report table for accessions and accessionIDs. | E11: table | F11: NA | G11: naDomain | H11: naSpecimenSet | I11: naCompartmentSet | J11: naGroup | K11: naClass | L11: naNomenclature | M11: NA | N11: NA | O11: NA | P11: naUnitSet | Q11: naAggrScale | R11: naAggrSet | S11: NA | T11: NA | U11: active | V11: 2.2.2 | W11: 2.2.2 | X11: added in V2.2.2 | Y11: NA | Z11: NA | AA11: NA | AB11: NA | AC11: NA | AD11: NA | AE11: NA | AF11: NA | AG11: NA | AH11: NA | AI11: NA | AJ11: NA | AK11: NA | AL11: NA | AM11: NA | AN11: NA | AO11: NA | AP11: NA | AQ11: NA | AR11: NA | AS11: NA | AT11: NA | AU11: NA | AV11: NA | AW11: NA | AX11: NA | AY11: NA | AZ11: NA | BA11: NA | BB11: NA | BC11: NA | BD11: NA | BE11: NA | BF11: NA | BG11: NA | BH11: NA | BI11: NA | BJ11: NA | BK11: NA | BL11: NA | BM11: NA | BN11: NA | BO11: NA | BP11: NA | BQ11: NA | BR11: NA | BS11: NA | BT11: NA | BU11: NA | BV11: NA | BW11: NA | BX11: NA | BY11: NA | BZ11: NA | CA11: NA | CB11: NA | CC11: NA | CD11: NA | CE11: NA | CF11: NA | CG11: NA | CH11: NA | CI11: NA | CJ11: input | CK11: NA | CL11: NA | CM11: NA | CN11: varchar | CO11: NA | CP11: NA | CQ11: 0 | CR11: 30
A12: academ | B12: Academic institution | C12: categories | D12: The category of organization type used for academic institutions or research groups. | E12: NA | F12: NA | G12: naDomain | H12: naSpecimenSet | I12: naCompartmentSet | J12: naGroup | K12: naClass | L12: naNomenclature | M12: NA | N12: NA | O12: NA | P12: naUnitSet | Q12: naAggrScale | R12: naAggrSet | S12: NA | T12: NA | U12: active | V12: 2.0.0 | W12: 2.0.0 | X12: added in V2.0.0 | Y12: NA | Z12: NA | AA12: NA | AB12: NA | AC12: NA | AD12: NA | AE12: NA | AF12: NA | AG12: NA | AH12: NA | AI12: NA | AJ12: NA | AK12: NA | AL12: NA | AM12: NA | AN12: NA | AO12: NA | AP12: NA | AQ12: NA | AR12: NA | AS12: NA | AT12: NA | AU12: NA | AV12: NA | AW12: NA | AX12: NA | AY12: NA | AZ12: input | BA12: NA | BB12: NA | BC12: NA | BD12: NA | BE12: NA | BF12: NA | BG12: NA | BH12: NA | BI12: NA | BJ12: NA | BK12: NA | BL12: NA | BM12: NA | BN12: NA | BO12: NA | BP12: NA | BQ12: NA | BR12: NA | BS12: NA | BT12: NA | BU12: NA | BV12: NA | BW12: NA | BX12: NA | BY12: NA | BZ12: NA | CA12: NA | CB12: NA | CC12: NA | CD12: NA | CE12: NA | CF12: NA | CG12: NA | CH12: NA | CI12: NA | CJ12: input | CK12: NA | CL12: NA | CM12: NA | CN12: varchar | CO12: NA | CP12: NA | CQ12: 0 | CR12: 30
... A1617: delayArriv | B1617: Delayed Arrival or Prolonged Transit | C1617: qualityIndicators | D1617: A substantial delay (ie. of more than 14 days) between sample collection and the start of analysis. | E1617: NA | F1617: NA | G1617: naDomain | H1617: naSpecimenSet | I1617: naCompartmentSet | J1617: naGroup | K1617: naClass | L1617: naNomenclature | M1617: NA | N1617: NA | O1617: NA | P1617: naUnitSet | Q1617: naAggrScale | R1617: naAggrSet | S1617: NA | T1617: NA | U1617: active | V1617: 2.2.3 | W1617: 2.2.3 | X1617: added in V2.2.3 | Y1617: NA | Z1617: NA | AA1617: NA | AB1617: NA | AC1617: NA | AD1617: NA | AE1617: NA | AF1617: NA | AG1617: NA | AH1617: NA | AI1617: NA | AJ1617: NA | AK1617: NA | AL1617: NA | AM1617: NA | AN1617: NA | AO1617: NA | AP1617: NA | AQ1617: NA | AR1617: NA | AS1617: NA | AT1617: NA | AU1617: NA | AV1617: NA | AW1617: NA | AX1617: NA | AY1617: NA | AZ1617: NA | BA1617: NA | BB1617: NA | BC1617: NA | BD1617: NA | BE1617: NA | BF1617: NA | BG1617: NA | BH1617: NA | BI1617: NA | BJ1617: NA | BK1617: NA | BL1617: NA | BM1617: NA | BN1617: NA | BO1617: NA | BP1617: NA | BQ1617: NA | BR1617: NA | BS1617: NA | BT1617: NA | BU1617: input | BV1617: NA | BW1617: NA | BX1617: NA | BY1617: NA | BZ1617: NA | CA1617: NA | CB1617: NA | CC1617: NA | CD1617: NA | CE1617: NA | CF1617: NA | CG1617: NA | CH1617: NA | CI1617: NA | CJ1617: NA | CK1617: NA | CL1617: NA | CM1617: NA | CN1617: varchar | CO1617: NA | CP1617: NA | CQ1617: 0 | CR1617: 30

Sheet sets
A1: setCompID | B1: setID | C1: setType | D1: partID | E1: label | F1: enumeration | G1: status | H1: firstReleased | I1: lastUpdated | J1: changes | K1: notes
A2: absHumidUnitSet_gm3 | B2: absHumidUnitSet | C2: unitSets | D2: gm3 | E2: Gram per cubic metre | F2: 1 | G2: active | H2: 2.0.0 | I2: 2.0.0
A3: airCompartmentSet_air | B3: airCompartmentSet | C3: compartmentSets | D3: air | E3: Air compartment | F3: 1 | G3: active | H3: 2.0.0 | I3: 2.0.0
A4: airportSheetSet_airportLists | B4: airportSheetSet | C4: dictSets | D4: airportLists | E4: Airport lists worksheet | F4: 1 | G4: active | H4: 2.0.0 | I4: 2.0.0
A5: airportSheetSet_airportTemplate | B5: airportSheetSet | C5: dictSets | D5: airportTemplate | E5: Airport Surveillance Template | F5: 2 | G5: active | H5: 2.0.0 | I5: 2.0.0
A6: airSurfaceCompartmentSet_air | B6: airSurfaceCompartmentSet | C6: compartmentSets | D6: air | E6: Air compartment | F6: 1 | G6: active | H6: 2.0.0 | I6: 2.0.0
A7: airSurfaceCompartmentSet_surf | B7: airSurfaceCompartmentSet | C7: compartmentSets | D7: surf | E7: Surface compartment | F7: 2 | G7: active | H7: 2.0.0 | I7: 2.0.0
A8: airWaterCompartmentSet_air | B8: airWaterCompartmentSet | C8: compartmentSets | D8: air | E8: Air compartment | F8: 1 | G8: active | H8: 2.0.0 | I8: 2.0.0
A9: alleleUnitSet_ct | B9: alleleUnitSet | C9: unitSets | D9: ct | E9: Cycle threshold or quantification cycle (Ct or Cq) | F9: 1 | G9: active | H9: 2.0.0 | I9: 2.0.0
A10: alleleUnitSet_doc | B10: alleleUnitSet | C10: unitSets | D10: doc | E10: Depth of coverage | F10: 2 | G10: active | H10: 2.0.0 | I10: 2.0.0
A11: alleleUnitSet_gcCrA | B11: alleleUnitSet | C11: unitSets | D11: gcCrA | E11: Gene copies per copy of crAssphage | F11: 3 | G11: active | H11: 2.0.0 | I11: 2.0.0
A12: alleleUnitSet_gCGS | B12: alleleUnitSet | C12: unitSets | D12: gCGS | E12: Gene copies per gram solids | F12: 4 | G12: active | H12: 2.0.0 | I12: 2.0.0
A13: alleleUnitSet_gcMl | B13: alleleUnitSet | C13: unitSets | D13: gcMl | E13: Gene copies per mL | F13: 5 | G13: active | H13: 2.0.0 | I13: 2.0.0
A14: alleleUnitSet_gcDay100k | B14: alleleUnitSet | C14: unitSets | D14: gcDay100k | E14: gene copies per day per 100,000 people | F14: 6 | G14: active | H14: 2.0.0 | I14: 3.0.0 | J14: updated partID
A15: alleleUnitSet_det | B15: alleleUnitSet | C15: unitSets | D15: det | E15: Detected | F15: 7 | G15: active | H15: 1.1.0 | I15: 2.0.0
A16: alleleUnitSet_gcPpmov | B16: alleleUnitSet | C16: unitSets | D16: gcPpmov | E16: Gene copies per PMMoV copy | F16: 8 | G16: active | H16: 2.0.0 | I16: 2.0.0
A17: alleleUnitSet_slope | B17: alleleUnitSet | C17: unitSets | D17: slope | E17: slope | F17: 9 | G17: active | H17: 2.0.0 | I17: 2.0.0
A18: alleleUnitSet_inter | B18: alleleUnitSet | C18: unitSets | D18: inter | E18: Intercept | F18: 10 | G18: active | H18: 2.0.0 | I18: 2.0.0
A19: alleleUnitSet_efficient | B19: alleleUnitSet | C19: unitSets | D19: efficient | E19: Efficiency | F19: 11 | G19: active | H19: 2.0.0 | I19: 2.0.0
A20: alleleUnitSet_r2 | B20: alleleUnitSet | C20: unitSets | D20: r2 | E20: R squared | F20: 12 | G20: active | H20: 2.0.0 | I20: 2.0.0
A21: anyCompartmentSet_air | B21: anyCompartmentSet | C21: compartmentSets | D21: air | E21: Air compartment | F21: 1 | G21: active | H21: 2.0.0 | I21: 2.0.0
A22: anyCompartmentSet_surf | B22: anyCompartmentSet | C22: compartmentSets | D22: surf | E22: Surface compartment | F22: 2 | G22: active | H22: 2.0.0 | I22: 2.0.0
A23: anyCompartmentSet_wat | B23: anyCompartmentSet | C23: compartmentSets | D23: wat | E23: Water compartment | F23: 3 | G23: active | H23: 2.0.0 | I23: 2.0.0
A24: anySpecimenSet_pop | B24: anySpecimenSet | C24: specimenSets | D24: pop | E24: Population | F24: 1 | G24: active | H24: 2.0.0 | I24: 2.0.0
A25: anySpecimenSet_sa | B25: anySpecimenSet | C25: specimenSets | D25: sa | E25: Sample | F25: 2 | G25: active | H25: 2.0.0 | I25: 2.0.0
A26: anySpecimenSet_sit | B26: anySpecimenSet | C26: specimenSets | D26: sit | E26: Site | F26: 3 | G26: active | H26: 2.0.0 | I26: 2.0.0
... A178: geneticUnitSet_gcCrA | B178: geneticUnitSet | C178: unitSets | D178: gcCrA | E178: Gene copies per copy of crAssphage | F178: 7 | G178: active | H178: 2.0.0 | I178: 2.0.0
A179: geneticUnitSet_gcDay100k | B179: geneticUnitSet | C179: unitSets | D179: gcDay100k | E179: gene copies per day per 100,000 people | F179: 8 | G179: active | H179: 2.0.0 | I179: 3.0.0 | J179: updated partID
A180: geneticUnitSet_gCGS | B180: geneticUnitSet | C180: unitSets | D180: gCGS | E180: Gene copies per gram solids | F180: 9 | G180: active | H180: 2.0.0 | I180: 2.0.0
A181: geneticUnitSet_gcMl | B181: geneticUnitSet | C181: unitSets | D181: gcMl | E181: Gene copies per mL | F181: 10 | G181: active | H181: 2.0.0 | I181: 2.0.0
A182: geneticUnitSet_gcPpmov | B182: geneticUnitSet | C182: unitSets | D182: gcPpmov | E182: Gene copies per PMMoV copy | F182: 11 | G182: active | H182: 2.0.0 | I182: 2.0.0
A183: geneticUnitSet_gc | B183: geneticUnitSet | C183: unitSets | D183: gc | E183: Gene copies | F183: 12 | G183: active | H183: 2.0.0 | I183: 2.0.0
A184: geneticUnitSet_ct | B184: geneticUnitSet | C184: unitSets | D184: ct | E184: Cycle threshold or quantification cycle (Ct or Cq) | F184: 13 | G184: active | H184: 2.0.0 | I184: 2.0.0
A185: geneticUnitSet_slope | B185: geneticUnitSet | C185: unitSets | D185: slope | E185: slope | F185: 14 | G185: active | H185: 2.0.0 | I185: 2.0.0
A186: geneticUnitSet_inter | B186: geneticUnitSet | C186: unitSets | D186: inter | E186: Intercept | F186: 15 | G186: active | H186: 2.0.0 | I186: 2.0.0
A187: geneticUnitSet_efficient | B187: geneticUnitSet | C187: unitSets | D187: efficient | E187: Efficiency | F187: 16 | G187: active | H187: 2.0.0 | I187: 2.0.0
A188: geneticUnitSet_r2 | B188: geneticUnitSet | C188: unitSets | D188: r2 | E188: R squared | F188: 17 | G188: active | H188: 2.0.0 | I188: 2.0.0
A189: genMissingnessSet_restrict | B189: genMissingnessSet | C189: missingnessSets | D189: restrict | E189: Restricted data | F189: 0 | G189: active | H189: 2.3.0 | I189: 2.3.0
A190: genMissingnessSet_NULL | B190: genMissingnessSet | C190: missingnessSets | D190: NULL | E190: Null | F190: 555 | G190: active | H190: 2.0.0 | I190: 2.0.0
A191: genMissingnessSet_undisc | B191: genMissingnessSet | C191: missingnessSets | D191: undisc | E191: Undisclosed or Not Provided | F191: 666 | G191: active | H191: 2.0.0 | I191: 2.0.0
...

Sheet wideNames
A1: wideName | B1: label | C1: charLength | D1: descr | E1: source | F1: wideMeasure | G1: wideProtocol | H1: wideAttribute | I1: wideNameType | J1: reportTableName | K1: reportTableInput | L1: partTypeName | M1: partTypeInput | N1: compartmentName | O1: compartmentInput | P1: specimenName | Q1: specimenInput | R1: fractionName | S1: fractionInput | T1: measureName | U1: measureInput | V1: methodName | W1: methodInput | X1: unitName | Y1: unitInput | Z1: aggregationName | AA1: aggregationInput | AB1: index | AC1: attributeName | AD1: attributeInput | AE1: tag
A2: =IF(I2="attributes",H2,IF(I2="measurements",F2,G2)) -> 0 | B2: SampleID -Wide | C2: =LEN(A2) -> 0 | D2: A field for recording the unique identifier for a sample in a wide, or combined long and wide table. | E2: EU Airport template | F2: =IF(I2="measurements",IF(AE2="",_xlfn.CONCAT(O2,"_",Q2,"_",S2,"_",U2,"_",Y2,"_",AA2,"_",AB2,"_",AD2),_xlfn.CONCAT(O2,"_",Q2,"_",S2,"_",U2,"_",Y2,"_",AA2,"_",AB2,"_",AD2,".odm",AE2)),"NA") -> 0 | G2: =IF(I2="methods",IF(L2="measurement",IF(AE2="",_xlfn.CONCAT(K2,"_",M2,"_",O2,"_",Q2,"_",S2,"_",U2,"_",Y2,"_",AA2,"_",AB2,"_",AD2),_xlfn.CONCAT(K2,"_",M2,"_",O2,"_",Q2,"_",S2,"_",U2,"_",Y2,"_",AA2,"_",AB2,"_",AD2,".odm",AE2)),IF(AE2="",_xlfn.CONCAT(K2,"_",M2,"_",W2,"_",AD2),_xlfn.CONCAT(K2,"_",M2,"_",W2,"_",AD2,".odm",AE2))),"NA") -> 0 | H2: =IF(I2="attributes",IF(AE2="",_xlfn.CONCAT(K2,"_",AD2),_xlfn.CONCAT(K2,"_",AD2,".odm",AE2)),"NA") -> 0 | I2: attributes | J2: Sample report table Shorthand | K2: =IFERROR(VLOOKUP(J2,'wideName-Dropdowns'!$A:$B,2,FALSE),"") -> 0 | M2: =IFERROR(VLOOKUP(L2,'wideName-Dropdowns'!$C:$D,2,FALSE),"") -> 0 | O2: =IFERROR(VLOOKUP(N2,'wideName-Dropdowns'!$E:$F,2,FALSE),"") -> 0 | Q2: =IFERROR(VLOOKUP(P2,'wideName-Dropdowns'!$G:$H,2,FALSE),"") -> 0 | S2: =IFERROR(VLOOKUP(R2,'wideName-Dropdowns'!$I:$J,2,FALSE),"") -> 0 | U2: =IFERROR(VLOOKUP(T2,'wideName-Dropdowns'!$K:$L,2,FALSE),"") -> 0 | W2: =IFERROR(VLOOKUP(V2,'wideName-Dropdowns'!$M:$N,2,FALSE),"") -> 0 | Y2: =IFERROR(VLOOKUP(X2,'wideName-Dropdowns'!$O:$P,2,FALSE),"") -> 0 | AA2: =IFERROR(VLOOKUP(Z2,'wideName-Dropdowns'!$Q:$R,2,FALSE),"") -> 0 | AC2: Sample ID | AD2: =IFERROR(VLOOKUP(AC2,'wideName-Dropdowns'!$S:$T,2,FALSE),"") -> 0
A3: =IF(I3="attributes",H3,IF(I3="measurements",F3,G3)) -> 0 | B3: Airport IATA code | C3: =LEN(A3) -> 0 | D3: Airport IATA code for sampling, used as a parent site ID for organizing sub-sites in the airport. | E3: EU Airport template | F3: =IF(I3="measurements",IF(AE3="",_xlfn.CONCAT(O3,"_",Q3,"_",S3,"_",U3,"_",Y3,"_",AA3,"_",AB3,"_",AD3),_xlfn.CONCAT(O3,"_",Q3,"_",S3,"_",U3,"_",Y3,"_",AA3,"_",AB3,"_",AD3,".odm",AE3)),"NA") -> 0 | G3: =IF(I3="methods",IF(L3="measurement",IF(AE3="",_xlfn.CONCAT(K3,"_",M3,"_",O3,"_",Q3,"_",S3,"_",U3,"_",Y3,"_",AA3,"_",AB3,"_",AD3),_xlfn.CONCAT(K3,"_",M3,"_",O3,"_",Q3,"_",S3,"_",U3,"_",Y3,"_",AA3,"_",AB3,"_",AD3,".odm",AE3)),IF(AE3="",_xlfn.CONCAT(K3,"_",M3,"_",W3,"_",AD3),_xlfn.CONCAT(K3,"_",M3,"_",W3,"_",AD3,".odm",AE3))),"NA") -> 0 | H3: =IF(I3="attributes",IF(AE3="",_xlfn.CONCAT(K3,"_",AD3),_xlfn.CONCAT(K3,"_",AD3,".odm",AE3)),"NA") -> 0 | I3: attributes | J3: Sites table Shorthand | K3: =IFERROR(VLOOKUP(J3,'wideName-Dropdowns'!$A:$B,2,FALSE),"") -> 0 | M3: =IFERROR(VLOOKUP(L3,'wideName-Dropdowns'!$C:$D,2,FALSE),"") -> 0 | O3: =IFERROR(VLOOKUP(N3,'wideName-Dropdowns'!$E:$F,2,FALSE),"") -> 0 | Q3: =IFERROR(VLOOKUP(P3,'wideName-Dropdowns'!$G:$H,2,FALSE),"") -> 0 | S3: =IFERROR(VLOOKUP(R3,'wideName-Dropdowns'!$I:$J,2,FALSE),"") -> 0 | U3: =IFERROR(VLOOKUP(T3,'wideName-Dropdowns'!$K:$L,2,FALSE),"") -> 0 | W3: =IFERROR(VLOOKUP(V3,'wideName-Dropdowns'!$M:$N,2,FALSE),"") -> 0 | Y3: =IFERROR(VLOOKUP(X3,'wideName-Dropdowns'!$O:$P,2,FALSE),"") -> 0 | AA3: =IFERROR(VLOOKUP(Z3,'wideName-Dropdowns'!$Q:$R,2,FALSE),"") -> 0 | AC3: Parent Site ID | AD3: =IFERROR(VLOOKUP(AC3,'wideName-Dropdowns'!$S:$T,2,FALSE),"") -> 0
A4: =IF(I4="attributes",H4,IF(I4="measurements",F4,G4)) -> 0 | B4: Sample shed - wide | C4: =LEN(A4) -> 0 | D4: A geographic area, physical space, or structure. A sample is taken from a sampleshed for a representative measurement of a substance(s) in a wide, or combined long and wide table. | E4: EU Airport template | F4: =IF(I4="measurements",IF(AE4="",_xlfn.CONCAT(O4,"_",Q4,"_",S4,"_",U4,"_",Y4,"_",AA4,"_",AB4,"_",AD4),_xlfn.CONCAT(O4,"_",Q4,"_",S4,"_",U4,"_",Y4,"_",AA4,"_",AB4,"_",AD4,".odm",AE4)),"NA") -> 0 | G4: =IF(I4="methods",IF(L4="measurement",IF(AE4="",_xlfn.CONCAT(K4,"_",M4,"_",O4,"_",Q4,"_",S4,"_",U4,"_",Y4,"_",AA4,"_",AB4,"_",AD4),_xlfn.CONCAT(K4,"_",M4,"_",O4,"_",Q4,"_",S4,"_",U4,"_",Y4,"_",AA4,"_",AB4,"_",AD4,".odm",AE4)),IF(AE4="",_xlfn.CONCAT(K4,"_",M4,"_",W4,"_",AD4),_xlfn.CONCAT(K4,"_",M4,"_",W4,"_",AD4,".odm",AE4))),"NA") -> 0 | H4: =IF(I4="attributes",IF(AE4="",_xlfn.CONCAT(K4,"_",AD4),_xlfn.CONCAT(K4,"_",AD4,".odm",AE4)),"NA") -> 0 | I4: attributes | J4: Sites table Shorthand | K4: =IFERROR(VLOOKUP(J4,'wideName-Dropdowns'!$A:$B,2,FALSE),"") -> 0 | M4: =IFERROR(VLOOKUP(L4,'wideName-Dropdowns'!$C:$D,2,FALSE),"") -> 0 | O4: =IFERROR(VLOOKUP(N4,'wideName-Dropdowns'!$E:$F,2,FALSE),"") -> 0 | Q4: =IFERROR(VLOOKUP(P4,'wideName-Dropdowns'!$G:$H,2,FALSE),"") -> 0 | S4: =IFERROR(VLOOKUP(R4,'wideName-Dropdowns'!$I:$J,2,FALSE),"") -> 0 | U4: =IFERROR(VLOOKUP(T4,'wideName-Dropdowns'!$K:$L,2,FALSE),"") -> 0 | W4: =IFERROR(VLOOKUP(V4,'wideName-Dropdowns'!$M:$N,2,FALSE),"") -> 0 | Y4: =IFERROR(VLOOKUP(X4,'wideName-Dropdowns'!$O:$P,2,FALSE),"") -> 0 | AA4: =IFERROR(VLOOKUP(Z4,'wideName-Dropdowns'!$Q:$R,2,FALSE),"") -> 0 | AC4: Sample shed | AD4: =IFERROR(VLOOKUP(AC4,'wideName-Dropdowns'!$S:$T,2,FALSE),"") -> 0
A5: =IF(I5="attributes",H5,IF(I5="measurements",F5,G5)) -> 0 | B5: Site | C5: =LEN(A5) -> 0 | D5: A field for recording the unique identifier for a site in a wide, or combined long and wide table. | E5: EU Airport template | F5: =IF(I5="measurements",IF(AE5="",_xlfn.CONCAT(O5,"_",Q5,"_",S5,"_",U5,"_",Y5,"_",AA5,"_",AB5,"_",AD5),_xlfn.CONCAT(O5,"_",Q5,"_",S5,"_",U5,"_",Y5,"_",AA5,"_",AB5,"_",AD5,".odm",AE5)),"NA") -> 0 | G5: =IF(I5="methods",IF(L5="measurement",IF(AE5="",_xlfn.CONCAT(K5,"_",M5,"_",O5,"_",Q5,"_",S5,"_",U5,"_",Y5,"_",AA5,"_",AB5,"_",AD5),_xlfn.CONCAT(K5,"_",M5,"_",O5,"_",Q5,"_",S5,"_",U5,"_",Y5,"_",AA5,"_",AB5,"_",AD5,".odm",AE5)),IF(AE5="",_xlfn.CONCAT(K5,"_",M5,"_",W5,"_",AD5),_xlfn.CONCAT(K5,"_",M5,"_",W5,"_",AD5,".odm",AE5))),"NA") -> 0 | H5: =IF(I5="attributes",IF(AE5="",_xlfn.CONCAT(K5,"_",AD5),_xlfn.CONCAT(K5,"_",AD5,".odm",AE5)),"NA") -> 0 | I5: attributes | J5: Sites table Shorthand | K5: =IFERROR(VLOOKUP(J5,'wideName-Dropdowns'!$A:$B,2,FALSE),"") -> 0 | M5: =IFERROR(VLOOKUP(L5,'wideName-Dropdowns'!$C:$D,2,FALSE),"") -> 0 | O5: =IFERROR(VLOOKUP(N5,'wideName-Dropdowns'!$E:$F,2,FALSE),"") -> 0 | Q5: =IFERROR(VLOOKUP(P5,'wideName-Dropdowns'!$G:$H,2,FALSE),"") -> 0 | S5: =IFERROR(VLOOKUP(R5,'wideName-Dropdowns'!$I:$J,2,FALSE),"") -> 0 | U5: =IFERROR(VLOOKUP(T5,'wideName-Dropdowns'!$K:$L,2,FALSE),"") -> 0 | W5: =IFERROR(VLOOKUP(V5,'wideName-Dropdowns'!$M:$N,2,FALSE),"") -> 0 | Y5: =IFERROR(VLOOKUP(X5,'wideName-Dropdowns'!$O:$P,2,FALSE),"") -> 0 | AA5: =IFERROR(VLOOKUP(Z5,'wideName-Dropdowns'!$Q:$R,2,FALSE),"") -> 0 | AC5: Site ID | AD5: =IFERROR(VLOOKUP(AC5,'wideName-Dropdowns'!$S:$T,2,FALSE),"") -> 0
A6: =IF(I6="attributes",H6,IF(I6="measurements",F6,G6)) -> 0 | B6: Population served (PE) | C6: =LEN(A6) -> 0 | D6: A field for reporting the attribute of a site, which specifies the population of/population served by a given site in a wide or combined long-and-wide table. | E6: EU Airport template | F6: =IF(I6="measurements",IF(AE6="",_xlfn.CONCAT(O6,"_",Q6,"_",S6,"_",U6,"_",Y6,"_",AA6,"_",AB6,"_",AD6),_xlfn.CONCAT(O6,"_",Q6,"_",S6,"_",U6,"_",Y6,"_",AA6,"_",AB6,"_",AD6,".odm",AE6)),"NA") -> 0 | G6: =IF(I6="methods",IF(L6="measurement",IF(AE6="",_xlfn.CONCAT(K6,"_",M6,"_",O6,"_",Q6,"_",S6,"_",U6,"_",Y6,"_",AA6,"_",AB6,"_",AD6),_xlfn.CONCAT(K6,"_",M6,"_",O6,"_",Q6,"_",S6,"_",U6,"_",Y6,"_",AA6,"_",AB6,"_",AD6,".odm",AE6)),IF(AE6="",_xlfn.CONCAT(K6,"_",M6,"_",W6,"_",AD6),_xlfn.CONCAT(K6,"_",M6,"_",W6,"_",AD6,".odm",AE6))),"NA") -> 0 | H6: =IF(I6="attributes",IF(AE6="",_xlfn.CONCAT(K6,"_",AD6),_xlfn.CONCAT(K6,"_",AD6,".odm",AE6)),"NA") -> 0 | I6: measurements | J6: Measure report table Shorthand | K6: =IFERROR(VLOOKUP(J6,'wideName-Dropdowns'!$A:$B,2,FALSE),"") -> 0 | L6: Measures Part-type Shorthand | M6: =IFERROR(VLOOKUP(L6,'wideName-Dropdowns'!$C:$D,2,FALSE),"") -> 0 | N6: Human compartment | O6: =IFERROR(VLOOKUP(N6,'wideName-Dropdowns'!$E:$F,2,FALSE),"") -> 0 | P6: Site | Q6: =IFERROR(VLOOKUP(P6,'wideName-Dropdowns'!$G:$H,2,FALSE),"") -> 0 | R6: Not applicable | S6: =IFERROR(VLOOKUP(R6,'wideName-Dropdowns'!$I:$J,2,FALSE),"") -> 0 | T6: Population Served | U6: =IFERROR(VLOOKUP(T6,'wideName-Dropdowns'!$K:$L,2,FALSE),"") -> 0 | W6: =IFERROR(VLOOKUP(V6,'wideName-Dropdowns'!$M:$N,2,FALSE),"") -> 0 | X6: Number of people | Y6: =IFERROR(VLOOKUP(X6,'wideName-Dropdowns'!$O:$P,2,FALSE),"") -> 0 | Z6: Total amount or count - the sum | AA6: =IFERROR(VLOOKUP(Z6,'wideName-Dropdowns'!$Q:$R,2,FALSE),"") -> 0 | AB6: NA | AC6: Value | AD6: =IFERROR(VLOOKUP(AC6,'wideName-Dropdowns'!$S:$T,2,FALSE),"") -> 0
A7: =IF(I7="attributes",H7,IF(I7="measurements",F7,G7)) -> 0 | B7: Collection start date/time - wide | C7: =LEN(A7) -> 0 | D7: For integrated time averaged samples this is the date, time and timezone the sample was started being taken in a wide or combined long-and-wide table. | E7: EU Airport template | F7: =IF(I7="measurements",IF(AE7="",_xlfn.CONCAT(O7,"_",Q7,"_",S7,"_",U7,"_",Y7,"_",AA7,"_",AB7,"_",AD7),_xlfn.CONCAT(O7,"_",Q7,"_",S7,"_",U7,"_",Y7,"_",AA7,"_",AB7,"_",AD7,".odm",AE7)),"NA") -> 0 | G7: =IF(I7="methods",IF(L7="measurement",IF(AE7="",_xlfn.CONCAT(K7,"_",M7,"_",O7,"_",Q7,"_",S7,"_",U7,"_",Y7,"_",AA7,"_",AB7,"_",AD7),_xlfn.CONCAT(K7,"_",M7,"_",O7,"_",Q7,"_",S7,"_",U7,"_",Y7,"_",AA7,"_",AB7,"_",AD7,".odm",AE7)),IF(AE7="",_xlfn.CONCAT(K7,"_",M7,"_",W7,"_",AD7),_xlfn.CONCAT(K7,"_",M7,"_",W7,"_",AD7,".odm",AE7))),"NA") -> 0 | H7: =IF(I7="attributes",IF(AE7="",_xlfn.CONCAT(K7,"_",AD7),_xlfn.CONCAT(K7,"_",AD7,".odm",AE7)),"NA") -> 0 | I7: attributes | J7: Sample report table Shorthand | K7: =IFERROR(VLOOKUP(J7,'wideName-Dropdowns'!$A:$B,2,FALSE),"") -> 0 | M7: =IFERROR(VLOOKUP(L7,'wideName-Dropdowns'!$C:$D,2,FALSE),"") -> 0 | O7: =IFERROR(VLOOKUP(N7,'wideName-Dropdowns'!$E:$F,2,FALSE),"") -> 0 | Q7: =IFERROR(VLOOKUP(P7,'wideName-Dropdowns'!$G:$H,2,FALSE),"") -> 0 | S7: =IFERROR(VLOOKUP(R7,'wideName-Dropdowns'!$I:$J,2,FALSE),"") -> 0 | U7: =IFERROR(VLOOKUP(T7,'wideName-Dropdowns'!$K:$L,2,FALSE),"") -> 0 | W7: =IFERROR(VLOOKUP(V7,'wideName-Dropdowns'!$M:$N,2,FALSE),"") -> 0 | Y7: =IFERROR(VLOOKUP(X7,'wideName-Dropdowns'!$O:$P,2,FALSE),"") -> 0 | AA7: =IFERROR(VLOOKUP(Z7,'wideName-Dropdowns'!$Q:$R,2,FALSE),"") -> 0 | AC7: Collection date time start | AD7: =IFERROR(VLOOKUP(AC7,'wideName-Dropdowns'!$S:$T,2,FALSE),"") -> 0
A8: =IF(I8="attributes",H8,IF(I8="measurements",F8,G8)) -> 0 | B8: Collection type - wide | C8: =LEN(A8) -> 0 | D8: The type of sample collection in a wide or combined long-and-wide table. | E8: EU Airport template | F8: =IF(I8="measurements",IF(AE8="",_xlfn.CONCAT(O8,"_",Q8,"_",S8,"_",U8,"_",Y8,"_",AA8,"_",AB8,"_",AD8),_xlfn.CONCAT(O8,"_",Q8,"_",S8,"_",U8,"_",Y8,"_",AA8,"_",AB8,"_",AD8,".odm",AE8)),"NA") -> 0 | G8: =IF(I8="methods",IF(L8="measurement",IF(AE8="",_xlfn.CONCAT(K8,"_",M8,"_",O8,"_",Q8,"_",S8,"_",U8,"_",Y8,"_",AA8,"_",AB8,"_",AD8),_xlfn.CONCAT(K8,"_",M8,"_",O8,"_",Q8,"_",S8,"_",U8,"_",Y8,"_",AA8,"_",AB8,"_",AD8,".odm",AE8)),IF(AE8="",_xlfn.CONCAT(K8,"_",M8,"_",W8,"_",AD8),_xlfn.CONCAT(K8,"_",M8,"_",W8,"_",AD8,".odm",AE8))),"NA") -> 0 | H8: =IF(I8="attributes",IF(AE8="",_xlfn.CONCAT(K8,"_",AD8),_xlfn.CONCAT(K8,"_",AD8,".odm",AE8)),"NA") -> 0 | I8: attributes | J8: Sample report table Shorthand | K8: =IFERROR(VLOOKUP(J8,'wideName-Dropdowns'!$A:$B,2,FALSE),"") -> 0 | M8: =IFERROR(VLOOKUP(L8,'wideName-Dropdowns'!$C:$D,2,FALSE),"") -> 0 | O8: =IFERROR(VLOOKUP(N8,'wideName-Dropdowns'!$E:$F,2,FALSE),"") -> 0 | Q8: =IFERROR(VLOOKUP(P8,'wideName-Dropdowns'!$G:$H,2,FALSE),"") -> 0 | S8: =IFERROR(VLOOKUP(R8,'wideName-Dropdowns'!$I:$J,2,FALSE),"") -> 0 | U8: =IFERROR(VLOOKUP(T8,'wideName-Dropdowns'!$K:$L,2,FALSE),"") -> 0 | W8: =IFERROR(VLOOKUP(V8,'wideName-Dropdowns'!$M:$N,2,FALSE),"") -> 0 | Y8: =IFERROR(VLOOKUP(X8,'wideName-Dropdowns'!$O:$P,2,FALSE),"") -> 0 | AA8: =IFERROR(VLOOKUP(Z8,'wideName-Dropdowns'!$Q:$R,2,FALSE),"") -> 0 | AC8: Sample collection type | AD8: =IFERROR(VLOOKUP(AC8,'wideName-Dropdowns'!$S:$T,2,FALSE),"") -> 0
A9: sm_2_collPer_collNum | B9: Composite collection number.period - wide | C9: =LEN(A9) -> 0 | D9: Composite collection number.period in a wide or combined long-and-wide table. | E9: EU Airport template | F9: =IF(I9="measurements",IF(AE9="",_xlfn.CONCAT(O9,"_",Q9,"_",S9,"_",U9,"_",Y9,"_",AA9,"_",AB9,"_",AD9),_xlfn.CONCAT(O9,"_",Q9,"_",S9,"_",U9,"_",Y9,"_",AA9,"_",AB9,"_",AD9,".odm",AE9)),"NA") -> 0 | G9: =IF(I9="methods",IF(L9="measurement",IF(AE9="",_xlfn.CONCAT(K9,"_",M9,"_",O9,"_",Q9,"_",S9,"_",U9,"_",Y9,"_",AA9,"_",AB9,"_",AD9),_xlfn.CONCAT(K9,"_",M9,"_",O9,"_",Q9,"_",S9,"_",U9,"_",Y9,"_",AA9,"_",AB9,"_",AD9,".odm",AE9)),IF(AE9="",_xlfn.CONCAT(K9,"_",M9,"_",W9,"_",AD9),_xlfn.CONCAT(K9,"_",M9,"_",W9,"_",AD9,".odm",AE9))),"NA") -> 0 | H9: =IF(I9="attributes",IF(AE9="",_xlfn.CONCAT(K9,"_",AD9),_xlfn.CONCAT(K9,"_",AD9,".odm",AE9)),"NA") -> 0 | I9: exceptions | K9: =IFERROR(VLOOKUP(J9,'wideName-Dropdowns'!$A:$B,2,FALSE),"") -> 0 | M9: =IFERROR(VLOOKUP(L9,'wideName-Dropdowns'!$C:$D,2,FALSE),"") -> 0 | O9: =IFERROR(VLOOKUP(N9,'wideName-Dropdowns'!$E:$F,2,FALSE),"") -> 0 | Q9: =IFERROR(VLOOKUP(P9,'wideName-Dropdowns'!$G:$H,2,FALSE),"") -> 0 | S9: =IFERROR(VLOOKUP(R9,'wideName-Dropdowns'!$I:$J,2,FALSE),"") -> 0 | U9: =IFERROR(VLOOKUP(T9,'wideName-Dropdowns'!$K:$L,2,FALSE),"") -> 0 | W9: =IFERROR(VLOOKUP(V9,'wideName-Dropdowns'!$M:$N,2,FALSE),"") -> 0 | Y9: =IFERROR(VLOOKUP(X9,'wideName-Dropdowns'!$O:$P,2,FALSE),"") -> 0 | AA9: =IFERROR(VLOOKUP(Z9,'wideName-Dropdowns'!$Q:$R,2,FALSE),"") -> 0 | AD9: =IFERROR(VLOOKUP(AC9,'wideName-Dropdowns'!$S:$T,2,FALSE),"") -> 0
A10: =IF(I10="attributes",H10,IF(I10="measurements",F10,G10)) -> 0 | B10: Pooled | C10: =LEN(A10) -> 0 | D10: Binary indicator for whether a sample is pooled/made by combining multiple distinct samples. | E10: EU Airport template | F10: =IF(I10="measurements",IF(AE10="",_xlfn.CONCAT(O10,"_",Q10,"_",S10,"_",U10,"_",Y10,"_",AA10,"_",AB10,"_",AD10),_xlfn.CONCAT(O10,"_",Q10,"_",S10,"_",U10,"_",Y10,"_",AA10,"_",AB10,"_",AD10,".odm",AE10)),"NA") -> 0 | G10: =IF(I10="methods",IF(L10="measurement",IF(AE10="",_xlfn.CONCAT(K10,"_",M10,"_",O10,"_",Q10,"_",S10,"_",U10,"_",Y10,"_",AA10,"_",AB10,"_",AD10),_xlfn.CONCAT(K10,"_",M10,"_",O10,"_",Q10,"_",S10,"_",U10,"_",Y10,"_",AA10,"_",AB10,"_",AD10,".odm",AE10)),IF(AE10="",_xlfn.CONCAT(K10,"_",M10,"_",W10,"_",AD10),_xlfn.CONCAT(K10,"_",M10,"_",W10,"_",AD10,".odm",AE10))),"NA") -> 0 | H10: =IF(I10="attributes",IF(AE10="",_xlfn.CONCAT(K10,"_",AD10),_xlfn.CONCAT(K10,"_",AD10,".odm",AE10)),"NA") -> 0 | I10: attributes | J10: Sample report table Shorthand | K10: =IFERROR(VLOOKUP(J10,'wideName-Dropdowns'!$A:$B,2,FALSE),"") -> 0 | M10: =IFERROR(VLOOKUP(L10,'wideName-Dropdowns'!$C:$D,2,FALSE),"") -> 0 | O10: =IFERROR(VLOOKUP(N10,'wideName-Dropdowns'!$E:$F,2,FALSE),"") -> 0 | Q10: =IFERROR(VLOOKUP(P10,'wideName-Dropdowns'!$G:$H,2,FALSE),"") -> 0 | S10: =IFERROR(VLOOKUP(R10,'wideName-Dropdowns'!$I:$J,2,FALSE),"") -> 0 | U10: =IFERROR(VLOOKUP(T10,'wideName-Dropdowns'!$K:$L,2,FALSE),"") -> 0 | W10: =IFERROR(VLOOKUP(V10,'wideName-Dropdowns'!$M:$N,2,FALSE),"") -> 0 | Y10: =IFERROR(VLOOKUP(X10,'wideName-Dropdowns'!$O:$P,2,FALSE),"") -> 0 | AA10: =IFERROR(VLOOKUP(Z10,'wideName-Dropdowns'!$Q:$R,2,FALSE),"") -> 0 | AC10: Pooled | AD10: =IFERROR(VLOOKUP(AC10,'wideName-Dropdowns'!$S:$T,2,FALSE),"") -> 0
A11: =IF(I11="attributes",H11,IF(I11="measurements",F11,G11)) -> 0 | B11: Analysis date/time start | C11: =LEN(A11) -> 0 | D11: Date, time, and timezone of when the analysis was started. | E11: EU Airport template | F11: =IF(I11="measurements",IF(AE11="",_xlfn.CONCAT(O11,"_",Q11,"_",S11,"_",U11,"_",Y11,"_",AA11,"_",AB11,"_",AD11),_xlfn.CONCAT(O11,"_",Q11,"_",S11,"_",U11,"_",Y11,"_",AA11,"_",AB11,"_",AD11,".odm",AE11)),"NA") -> 0 | G11: =IF(I11="methods",IF(L11="measurement",IF(AE11="",_xlfn.CONCAT(K11,"_",M11,"_",O11,"_",Q11,"_",S11,"_",U11,"_",Y11,"_",AA11,"_",AB11,"_",AD11),_xlfn.CONCAT(K11,"_",M11,"_",O11,"_",Q11,"_",S11,"_",U11,"_",Y11,"_",AA11,"_",AB11,"_",AD11,".odm",AE11)),IF(AE11="",_xlfn.CONCAT(K11,"_",M11,"_",W11,"_",AD11),_xlfn.CONCAT(K11,"_",M11,"_",W11,"_",AD11,".odm",AE11))),"NA") -> 0 | H11: =IF(I11="attributes",IF(AE11="",_xlfn.CONCAT(K11,"_",AD11),_xlfn.CONCAT(K11,"_",AD11,".odm",AE11)),"NA") -> 0 | I11: attributes | J11: Measure report table Shorthand | K11: =IFERROR(VLOOKUP(J11,'wideName-Dropdowns'!$A:$B,2,FALSE),"") -> 0 | M11: =IFERROR(VLOOKUP(L11,'wideName-Dropdowns'!$C:$D,2,FALSE),"") -> 0 | O11: =IFERROR(VLOOKUP(N11,'wideName-Dropdowns'!$E:$F,2,FALSE),"") -> 0 | Q11: =IFERROR(VLOOKUP(P11,'wideName-Dropdowns'!$G:$H,2,FALSE),"") -> 0 | S11: =IFERROR(VLOOKUP(R11,'wideName-Dropdowns'!$I:$J,2,FALSE),"") -> 0 | U11: =IFERROR(VLOOKUP(T11,'wideName-Dropdowns'!$K:$L,2,FALSE),"") -> 0 | W11: =IFERROR(VLOOKUP(V11,'wideName-Dropdowns'!$M:$N,2,FALSE),"") -> 0 | Y11: =IFERROR(VLOOKUP(X11,'wideName-Dropdowns'!$O:$P,2,FALSE),"") -> 0 | AA11: =IFERROR(VLOOKUP(Z11,'wideName-Dropdowns'!$Q:$R,2,FALSE),"") -> 0 | AC11: Analysis date start | AD11: =IFERROR(VLOOKUP(AC11,'wideName-Dropdowns'!$S:$T,2,FALSE),"") -> 0
A12: =IF(I12="attributes",H12,IF(I12="measurements",F12,G12)) -> 0 | B12: Analysis date/time end | C12: =LEN(A12) -> 0 | D12: Date, time, and timezone of when the analysis was completed. | E12: EU Airport template | F12: =IF(I12="measurements",IF(AE12="",_xlfn.CONCAT(O12,"_",Q12,"_",S12,"_",U12,"_",Y12,"_",AA12,"_",AB12,"_",AD12),_xlfn.CONCAT(O12,"_",Q12,"_",S12,"_",U12,"_",Y12,"_",AA12,"_",AB12,"_",AD12,".odm",AE12)),"NA") -> 0 | G12: =IF(I12="methods",IF(L12="measurement",IF(AE12="",_xlfn.CONCAT(K12,"_",M12,"_",O12,"_",Q12,"_",S12,"_",U12,"_",Y12,"_",AA12,"_",AB12,"_",AD12),_xlfn.CONCAT(K12,"_",M12,"_",O12,"_",Q12,"_",S12,"_",U12,"_",Y12,"_",AA12,"_",AB12,"_",AD12,".odm",AE12)),IF(AE12="",_xlfn.CONCAT(K12,"_",M12,"_",W12,"_",AD12),_xlfn.CONCAT(K12,"_",M12,"_",W12,"_",AD12,".odm",AE12))),"NA") -> 0 | H12: =IF(I12="attributes",IF(AE12="",_xlfn.CONCAT(K12,"_",AD12),_xlfn.CONCAT(K12,"_",AD12,".odm",AE12)),"NA") -> 0 | I12: attributes | J12: Measure report table Shorthand | K12: =IFERROR(VLOOKUP(J12,'wideName-Dropdowns'!$A:$B,2,FALSE),"") -> 0 | M12: =IFERROR(VLOOKUP(L12,'wideName-Dropdowns'!$C:$D,2,FALSE),"") -> 0 | O12: =IFERROR(VLOOKUP(N12,'wideName-Dropdowns'!$E:$F,2,FALSE),"") -> 0 | Q12: =IFERROR(VLOOKUP(P12,'wideName-Dropdowns'!$G:$H,2,FALSE),"") -> 0 | S12: =IFERROR(VLOOKUP(R12,'wideName-Dropdowns'!$I:$J,2,FALSE),"") -> 0 | U12: =IFERROR(VLOOKUP(T12,'wideName-Dropdowns'!$K:$L,2,FALSE),"") -> 0 | W12: =IFERROR(VLOOKUP(V12,'wideName-Dropdowns'!$M:$N,2,FALSE),"") -> 0 | Y12: =IFERROR(VLOOKUP(X12,'wideName-Dropdowns'!$O:$P,2,FALSE),"") -> 0 | AA12: =IFERROR(VLOOKUP(Z12,'wideName-Dropdowns'!$Q:$R,2,FALSE),"") -> 0 | AC12: Analysis date end | AD12: =IFERROR(VLOOKUP(AC12,'wideName-Dropdowns'!$S:$T,2,FALSE),"") -> 0
A13: =IF(I13="attributes",H13,IF(I13="measurements",F13,G13)) -> 0 | B13: Fraction analyzed | C13: =LEN(A13) -> 0 | D13: The fraction of the wastewater used for analysis and measurement. | E13: EU Airport template | F13: =IF(I13="measurements",IF(AE13="",_xlfn.CONCAT(O13,"_",Q13,"_",S13,"_",U13,"_",Y13,"_",AA13,"_",AB13,"_",AD13),_xlfn.CONCAT(O13,"_",Q13,"_",S13,"_",U13,"_",Y13,"_",AA13,"_",AB13,"_",AD13,".odm",AE13)),"NA") -> 0 | G13: =IF(I13="methods",IF(L13="measurement",IF(AE13="",_xlfn.CONCAT(K13,"_",M13,"_",O13,"_",Q13,"_",S13,"_",U13,"_",Y13,"_",AA13,"_",AB13,"_",AD13),_xlfn.CONCAT(K13,"_",M13,"_",O13,"_",Q13,"_",S13,"_",U13,"_",Y13,"_",AA13,"_",AB13,"_",AD13,".odm",AE13)),IF(AE13="",_xlfn.CONCAT(K13,"_",M13,"_",W13,"_",AD13),_xlfn.CONCAT(K13,"_",M13,"_",W13,"_",AD13,".odm",AE13))),"NA") -> 0 | H13: =IF(I13="attributes",IF(AE13="",_xlfn.CONCAT(K13,"_",AD13),_xlfn.CONCAT(K13,"_",AD13,".odm",AE13)),"NA") -> 0 | I13: attributes | J13: Measure report table Shorthand | K13: =IFERROR(VLOOKUP(J13,'wideName-Dropdowns'!$A:$B,2,FALSE),"") -> 0 | M13: =IFERROR(VLOOKUP(L13,'wideName-Dropdowns'!$C:$D,2,FALSE),"") -> 0 | O13: =IFERROR(VLOOKUP(N13,'wideName-Dropdowns'!$E:$F,2,FALSE),"") -> 0 | Q13: =IFERROR(VLOOKUP(P13,'wideName-Dropdowns'!$G:$H,2,FALSE),"") -> 0 | S13: =IFERROR(VLOOKUP(R13,'wideName-Dropdowns'!$I:$J,2,FALSE),"") -> 0 | U13: =IFERROR(VLOOKUP(T13,'wideName-Dropdowns'!$K:$L,2,FALSE),"") -> 0 | W13: =IFERROR(VLOOKUP(V13,'wideName-Dropdowns'!$M:$N,2,FALSE),"") -> 0 | Y13: =IFERROR(VLOOKUP(X13,'wideName-Dropdowns'!$O:$P,2,FALSE),"") -> 0 | AA13: =IFERROR(VLOOKUP(Z13,'wideName-Dropdowns'!$Q:$R,2,FALSE),"") -> 0 | AC13: Fraction analyzed | AD13: =IFERROR(VLOOKUP(AC13,'wideName-Dropdowns'!$S:$T,2,FALSE),"") -> 0
A14: =IF(I14="attributes",H14,IF(I14="measurements",F14,G14)) -> 0 | B14: Sample type | C14: =LEN(A14) -> 0 | D14: The type of sample. | E14: EU Airport template | F14: =IF(I14="measurements",IF(AE14="",_xlfn.CONCAT(O14,"_",Q14,"_",S14,"_",U14,"_",Y14,"_",AA14,"_",AB14,"_",AD14),_xlfn.CONCAT(O14,"_",Q14,"_",S14,"_",U14,"_",Y14,"_",AA14,"_",AB14,"_",AD14,".odm",AE14)),"NA") -> 0 | G14: =IF(I14="methods",IF(L14="measurement",IF(AE14="",_xlfn.CONCAT(K14,"_",M14,"_",O14,"_",Q14,"_",S14,"_",U14,"_",Y14,"_",AA14,"_",AB14,"_",AD14),_xlfn.CONCAT(K14,"_",M14,"_",O14,"_",Q14,"_",S14,"_",U14,"_",Y14,"_",AA14,"_",AB14,"_",AD14,".odm",AE14)),IF(AE14="",_xlfn.CONCAT(K14,"_",M14,"_",W14,"_",AD14),_xlfn.CONCAT(K14,"_",M14,"_",W14,"_",AD14,".odm",AE14))),"NA") -> 0 | H14: =IF(I14="attributes",IF(AE14="",_xlfn.CONCAT(K14,"_",AD14),_xlfn.CONCAT(K14,"_",AD14,".odm",AE14)),"NA") -> 0 | I14: attributes | J14: Sample report table Shorthand | K14: =IFERROR(VLOOKUP(J14,'wideName-Dropdowns'!$A:$B,2,FALSE),"") -> 0 | M14: =IFERROR(VLOOKUP(L14,'wideName-Dropdowns'!$C:$D,2,FALSE),"") -> 0 | O14: =IFERROR(VLOOKUP(N14,'wideName-Dropdowns'!$E:$F,2,FALSE),"") -> 0 | Q14: =IFERROR(VLOOKUP(P14,'wideName-Dropdowns'!$G:$H,2,FALSE),"") -> 0 | S14: =IFERROR(VLOOKUP(R14,'wideName-Dropdowns'!$I:$J,2,FALSE),"") -> 0 | U14: =IFERROR(VLOOKUP(T14,'wideName-Dropdowns'!$K:$L,2,FALSE),"") -> 0 | W14: =IFERROR(VLOOKUP(V14,'wideName-Dropdowns'!$M:$N,2,FALSE),"") -> 0 | Y14: =IFERROR(VLOOKUP(X14,'wideName-Dropdowns'!$O:$P,2,FALSE),"") -> 0 | AA14: =IFERROR(VLOOKUP(Z14,'wideName-Dropdowns'!$Q:$R,2,FALSE),"") -> 0 | AC14: Sample material | AD14: =IFERROR(VLOOKUP(AC14,'wideName-Dropdowns'!$S:$T,2,FALSE),"") -> 0
A15: ps_met_wat_sa_hFr_OR_2_pcrmeth_seqStrat_value | B15: Method used | C15: =LEN(A15) -> 0 | D15: The value for either the PCR method used, or the sequencing strategy used to obstain a measure in a wide or combined long-and-wide table. | E15: EU Airport template | F15: =IF(I15="measurements",IF(AE15="",_xlfn.CONCAT(O15,"_",Q15,"_",S15,"_",U15,"_",Y15,"_",AA15,"_",AB15,"_",AD15),_xlfn.CONCAT(O15,"_",Q15,"_",S15,"_",U15,"_",Y15,"_",AA15,"_",AB15,"_",AD15,".odm",AE15)),"NA") -> 0 | G15: =IF(I15="methods",IF(L15="measurement",IF(AE15="",_xlfn.CONCAT(K15,"_",M15,"_",O15,"_",Q15,"_",S15,"_",U15,"_",Y15,"_",AA15,"_",AB15,"_",AD15),_xlfn.CONCAT(K15,"_",M15,"_",O15,"_",Q15,"_",S15,"_",U15,"_",Y15,"_",AA15,"_",AB15,"_",AD15,".odm",AE15)),IF(AE15="",_xlfn.CONCAT(K15,"_",M15,"_",W15,"_",AD15),_xlfn.CONCAT(K15,"_",M15,"_",W15,"_",AD15,".odm",AE15))),"NA") -> 0 | H15: =IF(I15="attributes",IF(AE15="",_xlfn.CONCAT(K15,"_",AD15),_xlfn.CONCAT(K15,"_",AD15,".odm",AE15)),"NA") -> 0 | I15: exceptions | K15: =IFERROR(VLOOKUP(J15,'wideName-Dropdowns'!$A:$B,2,FALSE),"") -> 0 | M15: =IFERROR(VLOOKUP(L15,'wideName-Dropdowns'!$C:$D,2,FALSE),"") -> 0 | O15: =IFERROR(VLOOKUP(N15,'wideName-Dropdowns'!$E:$F,2,FALSE),"") -> 0 | Q15: =IFERROR(VLOOKUP(P15,'wideName-Dropdowns'!$G:$H,2,FALSE),"") -> 0 | S15: =IFERROR(VLOOKUP(R15,'wideName-Dropdowns'!$I:$J,2,FALSE),"") -> 0 | U15: =IFERROR(VLOOKUP(T15,'wideName-Dropdowns'!$K:$L,2,FALSE),"") -> 0 | W15: =IFERROR(VLOOKUP(V15,'wideName-Dropdowns'!$M:$N,2,FALSE),"") -> 0 | Y15: =IFERROR(VLOOKUP(X15,'wideName-Dropdowns'!$O:$P,2,FALSE),"") -> 0 | AA15: =IFERROR(VLOOKUP(Z15,'wideName-Dropdowns'!$Q:$R,2,FALSE),"") -> 0 | AD15: =IFERROR(VLOOKUP(AC15,'wideName-Dropdowns'!$S:$T,2,FALSE),"") -> 0
A16: =IF(I16="attributes",H16,IF(I16="measurements",F16,G16)) -> 0 | B16: Protocol citation link | C16: =LEN(A16) -> 0 | D16: Reference link for a specific protocol. | E16: EU Airport template | F16: =IF(I16="measurements",IF(AE16="",_xlfn.CONCAT(O16,"_",Q16,"_",S16,"_",U16,"_",Y16,"_",AA16,"_",AB16,"_",AD16),_xlfn.CONCAT(O16,"_",Q16,"_",S16,"_",U16,"_",Y16,"_",AA16,"_",AB16,"_",AD16,".odm",AE16)),"NA") -> 0 | G16: =IF(I16="methods",IF(L16="measurement",IF(AE16="",_xlfn.CONCAT(K16,"_",M16,"_",O16,"_",Q16,"_",S16,"_",U16,"_",Y16,"_",AA16,"_",AB16,"_",AD16),_xlfn.CONCAT(K16,"_",M16,"_",O16,"_",Q16,"_",S16,"_",U16,"_",Y16,"_",AA16,"_",AB16,"_",AD16,".odm",AE16)),IF(AE16="",_xlfn.CONCAT(K16,"_",M16,"_",W16,"_",AD16),_xlfn.CONCAT(K16,"_",M16,"_",W16,"_",AD16,".odm",AE16))),"NA") -> 0 | H16: =IF(I16="attributes",IF(AE16="",_xlfn.CONCAT(K16,"_",AD16),_xlfn.CONCAT(K16,"_",AD16,".odm",AE16)),"NA") -> 0 | I16: attributes | J16: Protocols table Shorthand | K16: =IFERROR(VLOOKUP(J16,'wideName-Dropdowns'!$A:$B,2,FALSE),"") -> 0 | M16: =IFERROR(VLOOKUP(L16,'wideName-Dropdowns'!$C:$D,2,FALSE),"") -> 0 | O16: =IFERROR(VLOOKUP(N16,'wideName-Dropdowns'!$E:$F,2,FALSE),"") -> 0 | Q16: =IFERROR(VLOOKUP(P16,'wideName-Dropdowns'!$G:$H,2,FALSE),"") -> 0 | S16: =IFERROR(VLOOKUP(R16,'wideName-Dropdowns'!$I:$J,2,FALSE),"") -> 0 | U16: =IFERROR(VLOOKUP(T16,'wideName-Dropdowns'!$K:$L,2,FALSE),"") -> 0 | W16: =IFERROR(VLOOKUP(V16,'wideName-Dropdowns'!$M:$N,2,FALSE),"") -> 0 | Y16: =IFERROR(VLOOKUP(X16,'wideName-Dropdowns'!$O:$P,2,FALSE),"") -> 0 | AA16: =IFERROR(VLOOKUP(Z16,'wideName-Dropdowns'!$Q:$R,2,FALSE),"") -> 0 | AC16: Reference link | AD16: =IFERROR(VLOOKUP(AC16,'wideName-Dropdowns'!$S:$T,2,FALSE),"") -> 0
A17: =IF(I17="attributes",H17,IF(I17="measurements",F17,G17)) -> 0 | B17: Target Type | C17: =LEN(A17) -> 0 | D17: The genetic "target type" as defined using ODM classes in a wide or combined long-and-wide table. | E17: EU Airport template | F17: =IF(I17="measurements",IF(AE17="",_xlfn.CONCAT(O17,"_",Q17,"_",S17,"_",U17,"_",Y17,"_",AA17,"_",AB17,"_",AD17),_xlfn.CONCAT(O17,"_",Q17,"_",S17,"_",U17,"_",Y17,"_",AA17,"_",AB17,"_",AD17,".odm",AE17)),"NA") -> 0 | G17: =IF(I17="methods",IF(L17="measurement",IF(AE17="",_xlfn.CONCAT(K17,"_",M17,"_",O17,"_",Q17,"_",S17,"_",U17,"_",Y17,"_",AA17,"_",AB17,"_",AD17),_xlfn.CONCAT(K17,"_",M17,"_",O17,"_",Q17,"_",S17,"_",U17,"_",Y17,"_",AA17,"_",AB17,"_",AD17,".odm",AE17)),IF(AE17="",_xlfn.CONCAT(K17,"_",M17,"_",W17,"_",AD17),_xlfn.CONCAT(K17,"_",M17,"_",W17,"_",AD17,".odm",AE17))),"NA") -> 0 | H17: =IF(I17="attributes",IF(AE17="",_xlfn.CONCAT(K17,"_",AD17),_xlfn.CONCAT(K17,"_",AD17,".odm",AE17)),"NA") -> 0 | I17: attributes | J17: Measure report table Shorthand | K17: =IFERROR(VLOOKUP(J17,'wideName-Dropdowns'!$A:$B,2,FALSE),"") -> 0 | M17: =IFERROR(VLOOKUP(L17,'wideName-Dropdowns'!$C:$D,2,FALSE),"") -> 0 | O17: =IFERROR(VLOOKUP(N17,'wideName-Dropdowns'!$E:$F,2,FALSE),"") -> 0 | Q17: =IFERROR(VLOOKUP(P17,'wideName-Dropdowns'!$G:$H,2,FALSE),"") -> 0 | S17: =IFERROR(VLOOKUP(R17,'wideName-Dropdowns'!$I:$J,2,FALSE),"") -> 0 | U17: =IFERROR(VLOOKUP(T17,'wideName-Dropdowns'!$K:$L,2,FALSE),"") -> 0 | W17: =IFERROR(VLOOKUP(V17,'wideName-Dropdowns'!$M:$N,2,FALSE),"") -> 0 | Y17: =IFERROR(VLOOKUP(X17,'wideName-Dropdowns'!$O:$P,2,FALSE),"") -> 0 | AA17: =IFERROR(VLOOKUP(Z17,'wideName-Dropdowns'!$Q:$R,2,FALSE),"") -> 0 | AC17: Class | AD17: =IFERROR(VLOOKUP(AC17,'wideName-Dropdowns'!$S:$T,2,FALSE),"") -> 0
A18: =IF(I18="attributes",H18,IF(I18="measurements",F18,G18)) -> 0 | B18: Target | C18: =LEN(A18) -> 0 | D18: The genetic target or measure of an analysis in a wide or combined long-and-wide table. | E18: EU Airport template | F18: =IF(I18="measurements",IF(AE18="",_xlfn.CONCAT(O18,"_",Q18,"_",S18,"_",U18,"_",Y18,"_",AA18,"_",AB18,"_",AD18),_xlfn.CONCAT(O18,"_",Q18,"_",S18,"_",U18,"_",Y18,"_",AA18,"_",AB18,"_",AD18,".odm",AE18)),"NA") -> 0 | G18: =IF(I18="methods",IF(L18="measurement",IF(AE18="",_xlfn.CONCAT(K18,"_",M18,"_",O18,"_",Q18,"_",S18,"_",U18,"_",Y18,"_",AA18,"_",AB18,"_",AD18),_xlfn.CONCAT(K18,"_",M18,"_",O18,"_",Q18,"_",S18,"_",U18,"_",Y18,"_",AA18,"_",AB18,"_",AD18,".odm",AE18)),IF(AE18="",_xlfn.CONCAT(K18,"_",M18,"_",W18,"_",AD18),_xlfn.CONCAT(K18,"_",M18,"_",W18,"_",AD18,".odm",AE18))),"NA") -> 0 | H18: =IF(I18="attributes",IF(AE18="",_xlfn.CONCAT(K18,"_",AD18),_xlfn.CONCAT(K18,"_",AD18,".odm",AE18)),"NA") -> 0 | I18: attributes | J18: Measure report table Shorthand | K18: =IFERROR(VLOOKUP(J18,'wideName-Dropdowns'!$A:$B,2,FALSE),"") -> 0 | M18: =IFERROR(VLOOKUP(L18,'wideName-Dropdowns'!$C:$D,2,FALSE),"") -> 0 | O18: =IFERROR(VLOOKUP(N18,'wideName-Dropdowns'!$E:$F,2,FALSE),"") -> 0 | Q18: =IFERROR(VLOOKUP(P18,'wideName-Dropdowns'!$G:$H,2,FALSE),"") -> 0 | S18: =IFERROR(VLOOKUP(R18,'wideName-Dropdowns'!$I:$J,2,FALSE),"") -> 0 | U18: =IFERROR(VLOOKUP(T18,'wideName-Dropdowns'!$K:$L,2,FALSE),"") -> 0 | W18: =IFERROR(VLOOKUP(V18,'wideName-Dropdowns'!$M:$N,2,FALSE),"") -> 0 | Y18: =IFERROR(VLOOKUP(X18,'wideName-Dropdowns'!$O:$P,2,FALSE),"") -> 0 | AA18: =IFERROR(VLOOKUP(Z18,'wideName-Dropdowns'!$Q:$R,2,FALSE),"") -> 0 | AC18: Measure | AD18: =IFERROR(VLOOKUP(AC18,'wideName-Dropdowns'!$S:$T,2,FALSE),"") -> 0
A19: wat_sa_hFr_OR_3_otherM_otherA_otherV_hUn_hAg_value | B19: Target Other Specify | C19: =LEN(A19) -> 0 | D19: Value for an unlisted genetic target for either a mutation, an allele, or a variant in a wide or combined long-and-wide table. | E19: EU Airport template | F19: =IF(I19="measurements",IF(AE19="",_xlfn.CONCAT(O19,"_",Q19,"_",S19,"_",U19,"_",Y19,"_",AA19,"_",AB19,"_",AD19),_xlfn.CONCAT(O19,"_",Q19,"_",S19,"_",U19,"_",Y19,"_",AA19,"_",AB19,"_",AD19,".odm",AE19)),"NA") -> 0 | G19: =IF(I19="methods",IF(L19="measurement",IF(AE19="",_xlfn.CONCAT(K19,"_",M19,"_",O19,"_",Q19,"_",S19,"_",U19,"_",Y19,"_",AA19,"_",AB19,"_",AD19),_xlfn.CONCAT(K19,"_",M19,"_",O19,"_",Q19,"_",S19,"_",U19,"_",Y19,"_",AA19,"_",AB19,"_",AD19,".odm",AE19)),IF(AE19="",_xlfn.CONCAT(K19,"_",M19,"_",W19,"_",AD19),_xlfn.CONCAT(K19,"_",M19,"_",W19,"_",AD19,".odm",AE19))),"NA") -> 0 | H19: =IF(I19="attributes",IF(AE19="",_xlfn.CONCAT(K19,"_",AD19),_xlfn.CONCAT(K19,"_",AD19,".odm",AE19)),"NA") -> 0 | I19: exceptions | K19: =IFERROR(VLOOKUP(J19,'wideName-Dropdowns'!$A:$B,2,FALSE),"") -> 0 | M19: =IFERROR(VLOOKUP(L19,'wideName-Dropdowns'!$C:$D,2,FALSE),"") -> 0 | O19: =IFERROR(VLOOKUP(N19,'wideName-Dropdowns'!$E:$F,2,FALSE),"") -> 0 | Q19: =IFERROR(VLOOKUP(P19,'wideName-Dropdowns'!$G:$H,2,FALSE),"") -> 0 | S19: =IFERROR(VLOOKUP(R19,'wideName-Dropdowns'!$I:$J,2,FALSE),"") -> 0 | U19: =IFERROR(VLOOKUP(T19,'wideName-Dropdowns'!$K:$L,2,FALSE),"") -> 0 | W19: =IFERROR(VLOOKUP(V19,'wideName-Dropdowns'!$M:$N,2,FALSE),"") -> 0 | Y19: =IFERROR(VLOOKUP(X19,'wideName-Dropdowns'!$O:$P,2,FALSE),"") -> 0 | AA19: =IFERROR(VLOOKUP(Z19,'wideName-Dropdowns'!$Q:$R,2,FALSE),"") -> 0 | AD19: =IFERROR(VLOOKUP(AC19,'wideName-Dropdowns'!$S:$T,2,FALSE),"") -> 0
A20: =IF(I20="attributes",H20,IF(I20="measurements",F20,G20)) -> 0 | B20: Value - wide | C20: =LEN(A20) -> 0 | D20: Measure value in a wide or combined long-and-wide table where most details are recorded in other columns. | E20: EU Airport template | F20: =IF(I20="measurements",IF(AE20="",_xlfn.CONCAT(O20,"_",Q20,"_",S20,"_",U20,"_",Y20,"_",AA20,"_",AB20,"_",AD20),_xlfn.CONCAT(O20,"_",Q20,"_",S20,"_",U20,"_",Y20,"_",AA20,"_",AB20,"_",AD20,".odm",AE20)),"NA") -> 0 | G20: =IF(I20="methods",IF(L20="measurement",IF(AE20="",_xlfn.CONCAT(K20,"_",M20,"_",O20,"_",Q20,"_",S20,"_",U20,"_",Y20,"_",AA20,"_",AB20,"_",AD20),_xlfn.CONCAT(K20,"_",M20,"_",O20,"_",Q20,"_",S20,"_",U20,"_",Y20,"_",AA20,"_",AB20,"_",AD20,".odm",AE20)),IF(AE20="",_xlfn.CONCAT(K20,"_",M20,"_",W20,"_",AD20),_xlfn.CONCAT(K20,"_",M20,"_",W20,"_",AD20,".odm",AE20))),"NA") -> 0 | H20: =IF(I20="attributes",IF(AE20="",_xlfn.CONCAT(K20,"_",AD20),_xlfn.CONCAT(K20,"_",AD20,".odm",AE20)),"NA") -> 0 | I20: measurements | K20: =IFERROR(VLOOKUP(J20,'wideName-Dropdowns'!$A:$B,2,FALSE),"") -> 0 | M20: =IFERROR(VLOOKUP(L20,'wideName-Dropdowns'!$C:$D,2,FALSE),"") -> 0 | N20: Water compartment | O20: =IFERROR(VLOOKUP(N20,'wideName-Dropdowns'!$E:$F,2,FALSE),"") -> 0 | P20: Sample | Q20: =IFERROR(VLOOKUP(P20,'wideName-Dropdowns'!$G:$H,2,FALSE),"") -> 0 | R20: See Header for Fraction Analyzed | S20: =IFERROR(VLOOKUP(R20,'wideName-Dropdowns'!$I:$J,2,FALSE),"") -> 0 | T20: See Header for Measure | U20: =IFERROR(VLOOKUP(T20,'wideName-Dropdowns'!$K:$L,2,FALSE),"") -> 0 | W20: =IFERROR(VLOOKUP(V20,'wideName-Dropdowns'!$M:$N,2,FALSE),"") -> 0 | X20: See Header for Unit | Y20: =IFERROR(VLOOKUP(X20,'wideName-Dropdowns'!$O:$P,2,FALSE),"") -> 0 | Z20: See Header for Aggregation | AA20: =IFERROR(VLOOKUP(Z20,'wideName-Dropdowns'!$Q:$R,2,FALSE),"") -> 0 | AB20: NR | AC20: Value | AD20: =IFERROR(VLOOKUP(AC20,'wideName-Dropdowns'!$S:$T,2,FALSE),"") -> 0
A21: =IF(I21="attributes",H21,IF(I21="measurements",F21,G21)) -> 0 | B21: Unit - wide | C21: =LEN(A21) -> 0 | D21: The unit of a measure in a wide or combined long-and-wide table. | E21: EU Airport template | F21: =IF(I21="measurements",IF(AE21="",_xlfn.CONCAT(O21,"_",Q21,"_",S21,"_",U21,"_",Y21,"_",AA21,"_",AB21,"_",AD21),_xlfn.CONCAT(O21,"_",Q21,"_",S21,"_",U21,"_",Y21,"_",AA21,"_",AB21,"_",AD21,".odm",AE21)),"NA") -> 0 | G21: =IF(I21="methods",IF(L21="measurement",IF(AE21="",_xlfn.CONCAT(K21,"_",M21,"_",O21,"_",Q21,"_",S21,"_",U21,"_",Y21,"_",AA21,"_",AB21,"_",AD21),_xlfn.CONCAT(K21,"_",M21,"_",O21,"_",Q21,"_",S21,"_",U21,"_",Y21,"_",AA21,"_",AB21,"_",AD21,".odm",AE21)),IF(AE21="",_xlfn.CONCAT(K21,"_",M21,"_",W21,"_",AD21),_xlfn.CONCAT(K21,"_",M21,"_",W21,"_",AD21,".odm",AE21))),"NA") -> 0 | H21: =IF(I21="attributes",IF(AE21="",_xlfn.CONCAT(K21,"_",AD21),_xlfn.CONCAT(K21,"_",AD21,".odm",AE21)),"NA") -> 0 | I21: attributes | J21: Measure report table Shorthand | K21: =IFERROR(VLOOKUP(J21,'wideName-Dropdowns'!$A:$B,2,FALSE),"") -> 0 | M21: =IFERROR(VLOOKUP(L21,'wideName-Dropdowns'!$C:$D,2,FALSE),"") -> 0 | O21: =IFERROR(VLOOKUP(N21,'wideName-Dropdowns'!$E:$F,2,FALSE),"") -> 0 | Q21: =IFERROR(VLOOKUP(P21,'wideName-Dropdowns'!$G:$H,2,FALSE),"") -> 0 | S21: =IFERROR(VLOOKUP(R21,'wideName-Dropdowns'!$I:$J,2,FALSE),"") -> 0 | U21: =IFERROR(VLOOKUP(T21,'wideName-Dropdowns'!$K:$L,2,FALSE),"") -> 0 | W21: =IFERROR(VLOOKUP(V21,'wideName-Dropdowns'!$M:$N,2,FALSE),"") -> 0 | Y21: =IFERROR(VLOOKUP(X21,'wideName-Dropdowns'!$O:$P,2,FALSE),"") -> 0 | AA21: =IFERROR(VLOOKUP(Z21,'wideName-Dropdowns'!$Q:$R,2,FALSE),"") -> 0 | AC21: Unit | AD21: =IFERROR(VLOOKUP(AC21,'wideName-Dropdowns'!$S:$T,2,FALSE),"") -> 0
